<?xml version="1.0" ?>
<robot name="kuka-omnirob-iisy" xmlns:controller="http://playerstage.sourceforge.net/gazebo/xmlschema/#controller" xmlns:interface="http://playerstage.sourceforge.net/gazebo/xmlschema/#interface" xmlns:sensor="http://playerstage.sourceforge.net/gazebo/xmlschema/#sensor" xmlns:xacro="http://www.ros.org/wiki/xacro">
    <!--static>true</static-->
    <link name="base_link">
        <inertial>
			<mass value="250" />
			<origin rpy="0 .0 0" xyz="0 -0.00000 0.24" />
			<inertia ixx="25.77086" ixy="-0.0" ixz="-0.0" iyy="53.79704" iyz="-0.0" izz="58.79601" />
		</inertial>
		<visual>
			<origin rpy="0 0 0" xyz="0 0 0" />
			<geometry>
				<mesh filename="../kuka-omnirob/meshes/omnirobBaseRot.dae" scale="1 1 1" />
			</geometry>
		</visual>
		<collision>
			<!--<origin rpy="0 0 0" xyz="0 0 0" />
			<geometry>
				<mesh filename="../kuka-omnirob/meshes/omnirobBaseRot.dae" scale="1 1 1" />
			</geometry> -->
			<origin rpy="0 0 0" xyz="0 0 0.35" />
			<geometry>
				<box size="0.915855 0.547 0.585000"/>
         	</geometry>
		</collision>
	</link>
    <gazebo reference="base_link">
    </gazebo>

	<link name="fr_laser_link">
		<inertial>
			<mass value="0.01" />
			<origin rpy="0 0 0" xyz="0.0 0.0 0.0" />
			<inertia ixx="1" ixy="0" ixz="0" iyy="1" iyz="0" izz="1" />
		</inertial>
		<visual>
			<origin rpy="0 0 0" xyz="0 0 0" />
			<geometry>
				<mesh filename="../kuka-omnirob/meshes/hokuyo.dae" scale="1 1 1" />
			</geometry>
		</visual>
		<collision>
			<origin rpy="0 0 0" xyz="0 0 0" />
			<geometry>
				<mesh filename="../kuka-omnirob/meshes/hokuyo.dae" scale="1 1 1" />
			</geometry>
		</collision>
	</link>
	<gazebo reference="fr_laser_link">
      <sensor type="ray" name="laser_front">
        <pose>0 0 0 0 0 0</pose>
        <visualize>false</visualize>
        <update_rate>40</update_rate>
        <ray>
          <scan>
            <horizontal>
              <samples>350</samples>
              <resolution>1</resolution>
              <min_angle>-3.141593</min_angle>
              <max_angle>1.570796</max_angle>
            </horizontal>
          </scan>
          <range>
            <min>0.10</min>
            <max>30.0</max>
            <resolution>0.01</resolution>
          </range>
          <noise>
            <type>gaussian</type>
            <mean>0.0</mean>
            <stddev>0.01</stddev>
          </noise>
        </ray>
		<plugin name="fr_laser_link" filename="libRayPlugin.so" />
      </sensor>
    </gazebo>

	<joint name="fr_laser_joint" type="fixed">
		<origin rpy="0 0 0" xyz="0.56029 -0.33 0.13937" />
		<parent link="base_link" />
		<child link="fr_laser_link" />
	</joint>
	<gazebo reference="fr_laser_joint">
	</gazebo>

	<link name="bl_laser_link">
		<inertial>
			<mass value="0.01" />
			<origin rpy="0 0 -1.570796" xyz="0.0 0.0 0.0" />
			<inertia ixx="1" ixy="0" ixz="0" iyy="1" iyz="0" izz="1" />
		</inertial>
		<visual>
			<origin rpy="0 0 0" xyz="0 0 0" />
			<geometry>
				<mesh filename="../kuka-omnirob/meshes/hokuyo.dae" scale="1 1 1" />
			</geometry>
		</visual>
		<collision>
			<origin rpy="0 0 0" xyz="0 0 0" />
			<geometry>
				<mesh filename="../kuka-omnirob/meshes/hokuyo.dae" scale="1 1 1" />
			</geometry>
		</collision>
	</link>
	<gazebo reference="bl_laser_link">
      <sensor type="ray" name="laser_back">
        <pose>0 0 0 0 0 0</pose>
        <visualize>false</visualize>
        <update_rate>40</update_rate>
        <ray>
          <scan>
            <horizontal>
              <samples>350</samples>
              <resolution>1</resolution>
              <min_angle>0</min_angle>
              <max_angle>4.71239</max_angle>
            </horizontal>
          </scan>
          <range>
            <min>0.10</min>
            <max>30.0</max>
            <resolution>0.01</resolution>
          </range>
          <noise>
            <type>gaussian</type>
            <mean>0.0</mean>
            <stddev>0.01</stddev>
          </noise>
        </ray>
		<plugin name="bl_laser_link" filename="libRayPlugin.so" />
      </sensor>
    </gazebo> 

	<joint name="bl_laser_joint" type="fixed">
		<origin rpy="0 0 0" xyz="-0.56029 0.33 0.13937" />
		<parent link="base_link" />
		<child link="bl_laser_link" />
	</joint>
	<gazebo reference="bl_laser_joint">
	</gazebo>


  <link name="bl_wheel">
		<inertial>
			<origin rpy="0 0 0" xyz="0 0 0" />
			<inertia ixx="0.012412" ixy="-0.000712" ixz="0.000503" iyy="0.015218" iyz="-0.000004" izz="0.011764" />
			<mass value="0.400000" />
		</inertial>
		<visual>
			<origin rpy="0 0 0" xyz="0 0.037 0" />
			<geometry>
				<mesh filename="../kuka-omnirob/meshes/omnirobBLWheelRot.dae" scale="1 1 1" />
			</geometry>
		</visual>
		<collision>
			<origin rpy="1.5708 0 0" xyz="0 0 0" />
			<geometry>
				<cylinder length="0.005" radius="0.125"/>
			</geometry>
			<surface>
			<friction>
				<ode>
				<mu>0</mu>
				<mu2>0</mu2>
				<fdir1>0 0 0</fdir1>
				<slip1>0</slip1>
				<slip2>0</slip2>
				</ode>
			</friction>
			<bounce>
				<restitution_coefficient>0</restitution_coefficient>
				<threshold>0</threshold>
			</bounce>
			<contact>
				<ode>
				<soft_cfm>0</soft_cfm>
				<soft_erp>0.200000</soft_erp>
				<kp>10000000000000.000000</kp>
				<kd>100000000000.000000</kd>
				<min_depth>0</min_depth>
				</ode>
			</contact>
			</surface>
			<laser_retro>0</laser_retro>
		</collision>
	</link>
	<gazebo reference="bl_wheel_link">
	</gazebo>

	<joint name="bl_wheel_joint" type="continuous">
		<origin rpy="0 3.14159 0" xyz="-0.347000 0.242000 0.130000" />
		<axis xyz="0 1 0" />
		<parent link="base_link" />
		<child link="bl_wheel" />
	</joint>
	<gazebo reference="bl_wheel_joint">
	</gazebo>

	<origin xyz="0 0 0" rpy="0 0 0" />

	<link name="br_wheel">
		<inertial>
			<origin rpy="0 0 0" xyz="0 0 0" />
			<inertia ixx="0.012412" ixy="-0.000712" ixz="0.000503" iyy="0.015218" iyz="-0.000004" izz="0.011764" />
			<mass value="0.400000" />
		</inertial>
		<visual>
			<origin rpy="0 0 0" xyz="0 -0.0 0" />
			<geometry>
				<mesh filename="../kuka-omnirob/meshes/omnirobBRWheelRot.dae" scale="1 1 1" />
			</geometry>
		</visual>
		<collision>
			<origin rpy="1.5708 0 0" xyz="0 0 0" />
			<geometry>
				<cylinder length="0.005" radius="0.125"/>
			</geometry>
			<surface>
			<friction>
				<ode>
				<mu>0</mu>
				<mu2>0</mu2>
				<fdir1>0 0 0</fdir1>
				<slip1>0</slip1>
				<slip2>0</slip2>
				</ode>
			</friction>
			<bounce>
				<restitution_coefficient>0</restitution_coefficient>
				<threshold>0</threshold>
			</bounce>
			<contact>
				<ode>
				<soft_cfm>0</soft_cfm>
				<soft_erp>0.200000</soft_erp>
				<kp>10000000000000.000000</kp>
				<kd>100000000000.000000</kd>
				<min_depth>0</min_depth>
				</ode>
			</contact>
			</surface>
			<laser_retro>0</laser_retro>
		</collision>
	</link>
	<gazebo reference="br_wheel_link">
	</gazebo>

	<joint name="br_wheel_joint" type="continuous">
		<origin rpy="0 0 0" xyz="-0.347000 -0.242000 0.130000" />
		<axis xyz="0 1 0" />
		<parent link="base_link" />
		<child link="br_wheel" />
	</joint>
	<gazebo reference="br_wheel_joint">
	</gazebo>

	<link name="fr_wheel">
		<inertial>
			<origin rpy="0 0 0" xyz="0 0 0" />
			<inertia ixx="0.012412" ixy="-0.000712" ixz="0.000503" iyy="0.015218" iyz="-0.000004" izz="0.011764" />
			<mass value="0.400000" />
		</inertial>
		<visual>
			<origin rpy="0 0 0" xyz="0 -0.0 0" />
			<geometry>
				<mesh filename="../kuka-omnirob/meshes/omnirobFRWheelRot.dae" scale="1 1 1" />
			</geometry>
		</visual>
		<collision>
			<origin rpy="1.5708 0 0" xyz="0 0 0" />
			<geometry>
				<cylinder length="0.005" radius="0.125"/>
			</geometry>
			<surface>
			<friction>
				<ode>
				<mu>0</mu>
				<mu2>0</mu2>
				<fdir1>0 0 0</fdir1>
				<slip1>0</slip1>
				<slip2>0</slip2>
				</ode>
			</friction>
			<bounce>
				<restitution_coefficient>0</restitution_coefficient>
				<threshold>0</threshold>
			</bounce>
			<contact>
				<ode>
				<soft_cfm>0</soft_cfm>
				<soft_erp>0.200000</soft_erp>
				<kp>10000000000000.000000</kp>
				<kd>100000000000.000000</kd>
				<min_depth>0</min_depth>
				</ode>
			</contact>
			</surface>
			<laser_retro>0</laser_retro>
		</collision>
	</link>
	<gazebo reference="fr_wheel_link">
	</gazebo>

	<joint name="fr_wheel_joint" type="continuous">
		<origin rpy="0 0 0" xyz="0.347000 -0.242000 0.130000" />
		<axis xyz="0 1 0" />
		<parent link="base_link" />
		<child link="fr_wheel" />
	</joint>
	<gazebo reference="fr_wheel_joint">
	</gazebo>

	<link name="fl_wheel">
		<inertial>
			<origin rpy="0 0 0" xyz="0 0 0" />
			<inertia ixx="0.012412" ixy="-0.000712" ixz="0.000503" iyy="0.015218" iyz="-0.000004" izz="0.011764" />
			<mass value="0.400000" />
		</inertial>
		<visual>
			<origin rpy="0 0 0" xyz="0 0.0 0" />
			<geometry>
				<mesh filename="../kuka-omnirob/meshes/omnirobFLWheelRot.dae" scale="1 1 1" />
			</geometry>
		</visual>
		<collision>
			<origin rpy="1.5708 0 0" xyz="0 0 0" />
			<geometry>
				<cylinder length="0.005" radius="0.125"/>
			</geometry>
			<surface>
			<friction>
				<ode>
				<mu>0</mu>
				<mu2>0</mu2>
				<fdir1>0 0 0</fdir1>
				<slip1>0</slip1>
				<slip2>0</slip2>
				</ode>
			</friction>
			<bounce>
				<restitution_coefficient>0</restitution_coefficient>
				<threshold>0</threshold>
			</bounce>
			<contact>
				<ode>
				<soft_cfm>0</soft_cfm>
				<soft_erp>0.200000</soft_erp>
				<kp>10000000000000.000000</kp>
				<kd>100000000000.000000</kd>
				<min_depth>0</min_depth>
				</ode>
			</contact>
			</surface>
			<laser_retro>0</laser_retro>
		</collision>
	</link>
	<gazebo reference="fl_wheel_link">
	</gazebo>

	<joint name="fl_wheel_joint" type="continuous">
		<origin rpy="0 0 0" xyz="0.347000 0.242000 0.130000" />
		<axis xyz="0 1 0" />
		<parent link="base_link" />
		<child link="fl_wheel" />
	</joint>
	<gazebo reference="fl_wheel_joint">
	</gazebo>

	<!-- ros2 control -->
  <ros2_control name="lbr_iisy15_r930" type="system">
    <hardware>
      <plugin>kuka_rsi_driver::KukaRSIHardwareInterface</plugin>
    </hardware>
    <!-- define joints and command/state interfaces for each joint -->
    <joint name="joint_1">
      <command_interface name="position"/>
      <state_interface name="position">
        <param name="initial_value">0.0</param>
      </state_interface>
    </joint>
    <joint name="joint_2">
      <command_interface name="position"/>
      <state_interface name="position">
        <param name="initial_value">-1.5708</param>
      </state_interface>
    </joint>
    <joint name="joint_3">
      <command_interface name="position"/>
      <state_interface name="position">
        <param name="initial_value">1.5708</param>
      </state_interface>
    </joint>
    <joint name="joint_4">
      <command_interface name="position"/>
      <state_interface name="position">
        <param name="initial_value">0.0</param>
      </state_interface>
    </joint>
    <joint name="joint_5">
      <command_interface name="position"/>
      <state_interface name="position">
        <param name="initial_value">0.0</param>
      </state_interface>
    </joint>
    <joint name="joint_6">
      <command_interface name="position"/>
      <state_interface name="position">
        <param name="initial_value">0.0</param>
      </state_interface>
    </joint>
    <gpio name="gpio"/>
  </ros2_control>
  <!-- links - main serial chain -->
  <link name="m_base_link">
    <collision>
      <geometry>
        <mesh filename="package://kuka_lbr_iisy_support/meshes/lbr_iisy15_r930/collision/base_link.stl"/>
      </geometry>
      <origin rpy="-0.0 0.0 -0.0" xyz="0.0 0.0 0.0"/>
    </collision>
    <inertial>
      <inertia ixx="1.0" ixy="0.0" ixz="0.0" iyy="1.0" iyz="0.0" izz="1.0"/>
      <mass value="8.666E0"/>
      <origin rpy="0.0 -0.0 0.0" xyz="0.0 0.0 0.0"/>
    </inertial>
    <visual>
      <geometry>
        <mesh filename="package://kuka_lbr_iisy_support/meshes/lbr_iisy15_r930/visual/base_link.stl"/>
      </geometry>
      <origin rpy="-0.0 0.0 -0.0" xyz="0.0 0.0 0.0"/>
      <material name="">
        <color rgba="0.9450980392156862 0.9254901960784314 1.0 1.0"/>
      </material>
    </visual>
  </link>
  <link name="link_1">
    <collision>
      <geometry>
        <mesh filename="package://kuka_lbr_iisy_support/meshes/lbr_iisy15_r930/collision/link_1.stl"/>
      </geometry>
      <origin rpy="-0.0 0.0 -0.0" xyz="0.0 0.0 0.0"/>
    </collision>
    <inertial>
      <inertia ixx="0.0489108039022503" ixy="0.0" ixz="0.0" iyy="0.0383705935400879" iyz="0.0" izz="0.0522121642769911"/>
      <mass value="9.62E0"/>
      <origin rpy="-1.3035636348359196 -0.7815781053554747 1.2529437882898196" xyz="0.00344301039501039 0.0191980353430353 -0.08662803846153849"/>
    </inertial>
    <visual>
      <geometry>
        <mesh filename="package://kuka_lbr_iisy_support/meshes/lbr_iisy15_r930/visual/link_1.stl"/>
      </geometry>
      <origin rpy="-0.0 0.0 -0.0" xyz="0.0 0.0 0.0"/>
      <material name="">
        <color rgba="0.9450980392156862 0.9254901960784314 1.0 1.0"/>
      </material>
    </visual>
  </link>
  <link name="link_2">
    <collision>
      <geometry>
        <mesh filename="package://kuka_lbr_iisy_support/meshes/lbr_iisy15_r930/collision/link_2.stl"/>
      </geometry>
      <origin rpy="-0.0 0.0 -0.0" xyz="0.0 0.0 0.0"/>
    </collision>
    <inertial>
      <inertia ixx="0.0306168627253135" ixy="0.0" ixz="0.0" iyy="0.252047093745431" iyz="0.0" izz="0.258650362609461"/>
      <mass value="8.079E0"/>
      <origin rpy="-0.017400716172763755 1.2184236596039677E-4 7.609596915052352E-4" xyz="0.144939171927219 4.90834261666048E-4 -0.0453728741180839"/>
    </inertial>
    <visual>
      <geometry>
        <mesh filename="package://kuka_lbr_iisy_support/meshes/lbr_iisy15_r930/visual/link_2.stl"/>
      </geometry>
      <origin rpy="-0.0 0.0 -0.0" xyz="0.0 0.0 0.0"/>
      <material name="">
        <color rgba="0.9450980392156862 0.9254901960784314 1.0 1.0"/>
      </material>
    </visual>
  </link>
  <link name="link_3">
    <collision>
      <geometry>
        <mesh filename="package://kuka_lbr_iisy_support/meshes/lbr_iisy15_r930/collision/link_3.stl"/>
      </geometry>
      <origin rpy="-0.0 0.0 -0.0" xyz="0.0 0.0 0.0"/>
    </collision>
    <inertial>
      <inertia ixx="0.0181557035426496" ixy="0.0" ixz="0.0" iyy="0.0346916391676837" iyz="0.0" izz="0.037776951242458"/>
      <mass value="7.6604E0"/>
      <origin rpy="0.1692981167548117 0.5271433699021747 -2.9605806714357508" xyz="0.0400709362435382 0.00400998642368544 0.0499127101717926"/>
    </inertial>
    <visual>
      <geometry>
        <mesh filename="package://kuka_lbr_iisy_support/meshes/lbr_iisy15_r930/visual/link_3.stl"/>
      </geometry>
      <origin rpy="-0.0 0.0 -0.0" xyz="0.0 0.0 0.0"/>
      <material name="">
        <color rgba="0.9450980392156862 0.9254901960784314 1.0 1.0"/>
      </material>
    </visual>
  </link>
  <link name="link_4">
    <collision>
      <geometry>
        <mesh filename="package://kuka_lbr_iisy_support/meshes/lbr_iisy15_r930/collision/link_4.stl"/>
      </geometry>
      <origin rpy="-0.0 0.0 -0.0" xyz="0.0 0.0 0.0"/>
    </collision>
    <inertial>
      <inertia ixx="0.0208771593304277" ixy="0.0" ixz="0.0" iyy="0.0526135698207455" iyz="0.0" izz="0.0587485883681802"/>
      <mass value="5.7014E0"/>
      <origin rpy="1.535166999601284 -1.2065715961818437 -1.512863903166617" xyz="0.00141160065948714 0.060839292103693904 -0.12025970463395"/>
    </inertial>
    <visual>
      <geometry>
        <mesh filename="package://kuka_lbr_iisy_support/meshes/lbr_iisy15_r930/visual/link_4.stl"/>
      </geometry>
      <origin rpy="-0.0 0.0 -0.0" xyz="0.0 0.0 0.0"/>
      <material name="">
        <color rgba="0.9450980392156862 0.9254901960784314 1.0 1.0"/>
      </material>
    </visual>
  </link>
  <link name="link_5">
    <collision>
      <geometry>
        <mesh filename="package://kuka_lbr_iisy_support/meshes/lbr_iisy15_r930/collision/link_5.stl"/>
      </geometry>
      <origin rpy="-0.0 0.0 -0.0" xyz="0.0 0.0 0.0"/>
    </collision>
    <inertial>
      <inertia ixx="0.00667288072123254" ixy="0.0" ixz="0.0" iyy="0.00503543168148481" iyz="0.0" izz="0.00841044585602456"/>
      <mass value="2.382E0"/>
      <origin rpy="0.4256203528755516 0.1454426479570896 1.2195648324165669" xyz="0.0365444794290512 -0.00829581863979849 -0.0371200125944584"/>
    </inertial>
    <visual>
      <geometry>
        <mesh filename="package://kuka_lbr_iisy_support/meshes/lbr_iisy15_r930/visual/link_5.stl"/>
      </geometry>
      <origin rpy="-0.0 0.0 -0.0" xyz="0.0 0.0 0.0"/>
      <material name="">
        <color rgba="0.9450980392156862 0.9254901960784314 1.0 1.0"/>
      </material>
    </visual>
  </link>
  <link name="link_6">
    <collision>
      <geometry>
        <mesh filename="package://kuka_lbr_iisy_support/meshes/lbr_iisy15_r930/collision/link_6.stl"/>
      </geometry>
      <origin rpy="-0.0 0.0 -0.0" xyz="0.0 0.0 0.0"/>
    </collision>
    <inertial>
      <inertia ixx="0.00390274036654823" ixy="0.0" ixz="0.0" iyy="0.00286930887521153" iyz="0.0" izz="0.00403512413298348"/>
      <mass value="1.509E0"/>
      <origin rpy="-0.051936335875096745 -0.1296523529795729 -0.0038347791577379832" xyz="-5.61365142478463E-4 0.00904387011265739 -0.0494449237905898"/>
    </inertial>
    <visual>
      <geometry>
        <mesh filename="package://kuka_lbr_iisy_support/meshes/lbr_iisy15_r930/visual/link_6.stl"/>
      </geometry>
      <origin rpy="-0.0 0.0 -0.0" xyz="0.0 0.0 0.0"/>
      <material name="">
        <color rgba="0.9450980392156862 0.9254901960784314 1.0 1.0"/>
      </material>
    </visual>
  </link>
  <!-- joints - main serial chain -->
  <joint name="m_base_link_joint" type="fixed">
    <parent link="base_link"/>
    <child link="m_base_link"/>
    <origin rpy="0 0 0" xyz="-0.3 0 0.6"/>
  </joint>
  <joint name="joint_1" type="revolute">
    <axis xyz="0.0 0.0 1.0"/>
    <child link="link_1"/>
    <limit effort="398.011277" lower="-3.2288591161895095E0" upper="3.2288591161895095E0" velocity="3.490656"/>
    <origin rpy="-3.141592653589793 0.0 -0.0" xyz="0.0 0.0 0.0"/>
    <parent link="m_base_link"/>
  </joint>
  <joint name="joint_2" type="revolute">
    <axis xyz="0.0 0.0 1.0"/>
    <child link="link_2"/>
    <limit effort="286.529873" lower="-4.014257279586958E0" upper="8.726646259971648E-1" velocity="3.490656"/>
    <origin rpy="1.5707963267948966 0.0 -0.0" xyz="0.0 0.0 -0.3"/>
    <parent link="link_1"/>
  </joint>
  <joint name="joint_3" type="revolute">
    <axis xyz="0.0 0.0 1.0"/>
    <child link="link_3"/>
    <limit effort="137.666701" lower="-2.6179938779914944E0" upper="2.6179938779914944E0" velocity="3.490656"/>
    <origin rpy="0.0 0.0 -1.5707963267948966" xyz="0.385 0.0 0.0"/>
    <parent link="link_2"/>
  </joint>
  <joint name="joint_4" type="revolute">
    <axis xyz="0.0 0.0 1.0"/>
    <child link="link_4"/>
    <limit effort="63.574238" lower="-3.141592653589793E0" upper="3.141592653589793E0" velocity="4.014255"/>
    <origin rpy="1.5707963267948966 0.0 -0.0" xyz="0.0 0.0 0.0"/>
    <parent link="link_3"/>
  </joint>
  <joint name="joint_5" type="revolute">
    <axis xyz="0.0 0.0 1.0"/>
    <child link="link_5"/>
    <limit effort="58.580298" lower="-1.9198621771937625E0" upper="1.9198621771937625E0" velocity="4.537856"/>
    <origin rpy="-1.5707963267948966 0.0 -0.0" xyz="0.0 0.0 -0.367"/>
    <parent link="link_4"/>
  </joint>
  <joint name="joint_6" type="revolute">
    <axis xyz="0.0 0.0 1.0"/>
    <child link="link_6"/>
    <limit effort="15.927568" lower="-3.839724354387525E0" upper="3.839724354387525E0" velocity="7.504909"/>
    <origin rpy="1.5707963267948966 0.0 -0.0" xyz="0.0 0.0 0.0"/>
    <parent link="link_5"/>
  </joint>
  <!-- ROS-Industrial 'base' frame - equivalent of 'KUKA ROBROOT'-->
  <link name="base"/>
  <joint name="m_base_link-base" type="fixed">
    <origin rpy="0 0 0" xyz="0 0 0"/>
    <parent link="m_base_link"/>
    <child link="base"/>
  </joint>
  <!-- ROS-Industrial 'flange' frame - attachment point for EEF models -->
  <link name="flange"/>
  <joint name="link6-flange" type="fixed">
    <child link="flange"/>
    <origin rpy="0 1.5707963267948966 -0.0" xyz="0.0 0.0 -0.178"/>
    <parent link="link_6"/>
  </joint>
  <!-- ROS-Industrial 'tool0' frame - all-zeros tool frame -->
  <link name="tool0"/>
  <joint name="link6-tool0" type="fixed">
    <child link="tool0"/>
    <origin rpy="0 3.141592653589793 -0.0" xyz="0.0 0.0 -0.178"/>
    <parent link="link_6"/>
  </joint>

</robot>